Workbook
Name SlicerCache_Table_1_Col_1: #N/A
Name SlicerCache_Table_1_Col_2: #N/A

Sheet Partnership Info
C2: Partner Name: | D2: Partner
C3: Davyn Limited | D3: ID
C5: Partner Development Manager | D5: Leon Ribeiro | F5: 🔗 Resources
C6: Partner Account Manager | D6: Edgar Balby | F6: Partner Portal
C7: Marketing Manager | D7: Agata Lech
C9: Partner Type | D9: Expert
C10: Market | D10: ROW
C11: Sale Commission % (12 months) | D11: 0.35
C12: Support | D12: TRUE
C13: Onboarding | D13: TRUE
C14: Avg. Onboarding amount | D14: 3000
C15: Support Commission % (lifetime) | D15: 0.2
C16: Connector/Integration Price (if any) | D16: 0
C18: Partner Customer base # | D18: 300
C19: Partner Customer base ICP (nº seats) | D19: 300

Sheet Plan Summary
C2: Plan Summary | D2: Q1 | G2: Q2 | J2: Q3 | M2: Q4 | Q2: Q1 | R2: Q2 | S2: Q3 | T2: Q4 | U2: Total Year 1 | W2: Year 2+ Services
D3: January | E3: February | F3: March | G3: April | H3: May | I3: June | J3: July | K3: August | L3: September | M3: October | N3: November | O3: December
C4: Won Customers # | D4: ='Business Plan'!E9 -> 1 | E4: ='Business Plan'!F9 -> 1 | F4: ='Business Plan'!G9 -> 2 | G4: ='Business Plan'!H9 -> 1 | H4: ='Business Plan'!I9 -> 2 | I4: ='Business Plan'!J9 -> 3 | J4: ='Business Plan'!K9 -> 2 | K4: ='Business Plan'!L9 -> 3 | ... O4: ='Business Plan'!P9 -> 1 | Q4: =SUM(D4:F4) -> 4 | R4: =SUM(G4:I4) -> 6 | S4: =SUM(J4:L4) -> 8 | T4: =SUM(M4:O4) -> 7 | U4: =SUM(D4:O4) -> 25 | W4: =SUM(F4:Q4) -> 27
E5: =D5 | F5: =E5 | G5: =F5 | H5: =G5 | I5: =H5 | J5: =I5 | K5: =J5 | L5: =K5 | ... O5: =N5
C6: Won MRR | D6: ='Business Plan'!E12 -> 1750 | E6: ='Business Plan'!F12 -> 2100 | F6: ='Business Plan'!G12 -> 2450 | G6: ='Business Plan'!H12 -> 2100 | H6: ='Business Plan'!I12 -> 2450 | I6: ='Business Plan'!J12 -> 4200 | J6: ='Business Plan'!K12 -> 2450 | K6: ='Business Plan'!L12 -> 2800 | ... O6: ='Business Plan'!P12 -> 2100 | Q6: =SUM(D6:F6) -> 6300 | R6: =SUM(G6:I6) -> 8750 | S6: =SUM(J6:L6) -> 9100 | T6: =SUM(M5:O6) -> 10850 | U6: =SUM(D6:O6) -> 35000
C7: Won ARR | D7: =D6*12 -> 21000 | E7: =E6*12 -> 25200 | F7: =F6*12 -> 29400 | G7: =G6*12 -> 25200 | H7: =H6*12 -> 29400 | I7: =I6*12 -> 50400 | J7: =J6*12 -> 29400 | K7: =K6*12 -> 33600 | ... O7: =O6*12 -> 25200 | Q7: =SUM(D7:F7) -> 75600 | R7: =SUM(G7:I7) -> 105000 | S7: =SUM(J7:L7) -> 109200 | T7: =SUM(M6:O7) -> 141050 | U7: =U6*12 -> 420000
C9: Total Commissions & Incentives | D9: =SUM(D19:D22) -> 8100 | E9: =SUM(E19:E22) -> 9570 | F9: =SUM(F19:F22) -> 28990 | G9: =SUM(G19:G22) -> 10320 | H9: =SUM(H19:H22) -> 13290 | I9: =SUM(I19:I22) -> 35690 | J9: =SUM(J19:J22) -> 16290 | K9: =SUM(K19:K22) -> 20760 | ... O9: =SUM(O19:O22) -> 26370 | Q9: =SUM(D9:F9) -> 46660 | R9: =SUM(G9:I9) -> 59300 | S9: =SUM(J9:L9) -> 76270 | T9: =SUM(M8:O9) -> 81120 | U9: =SUM(D9:O9) -> 263350 | W9: =U7*'Partnership Info'!D15 -> 84000
C11: Total Invested | D11: =(D25+D27)+D26 -> -15916.667 | E11: =(E25+E27)+E26 -> -25216.667 | F11: =(F25+F27)+F26 -> -15416.667 | G11: =(G25+G27)+G26 -> -15916.667 | H11: =(H25+H27)+H26 -> -22916.667 | I11: =(I25+I27)+I26 -> -15416.667 | J11: =(J25+J27)+J26 -> -23416.667 | K11: =(K25+K27)+K26 -> -15416.667 | ... O11: =(O25+O27)+O26 -> -15416.667 | Q11: =SUM(D11:F11) -> -56550 | R11: =SUM(G11:I11) -> -54250 | S11: =SUM(J11:L11) -> -54250 | T11: =SUM(M10:O11) -> -54250 | U11: =SUM(D11:O11) -> -219300 | W11: =Headcount!D37 -> 39750
C13: Total Balance (12-month P&L) | D13: =D9+D11 -> -7816.6667 | E13: =E9+E11 -> -15646.667 | F13: =F9+F11 -> 13573.333 | G13: =G9+G11 -> -5596.6667 | H13: =H9+H11 -> -9626.6667 | I13: =I9+I11 -> 20273.333 | J13: =J9+J11 -> -7126.6667 | K13: =K9+K11 -> 5343.3333 | ... O13: =O9+O11 -> 10953.333 | Q13: =SUM(D13:F13) -> -9890 | R13: =SUM(G13:I13) -> 5050 | S13: =SUM(J13:L13) -> 22020 | T13: =SUM(M12:O13) -> 26870 | U13: =SUM(D13:O13) -> 44050 | W13: =SUM(F13:Q13) -> 57623.333
C15: Commissions cashflow (new MRR only) | D15: ='Business Plan'!E26 -> 1362.5 | E15: ='Business Plan'!F26 -> 2097.5 | F15: ='Business Plan'!G26 -> 20905 | G15: ='Business Plan'!H26 -> 4440 | H15: ='Business Plan'!I26 -> 6797.5 | I15: ='Business Plan'!J26 -> 23317.5 | J15: ='Business Plan'!K26 -> 12125 | K15: ='Business Plan'!L26 -> 16105 | ... O15: ='Business Plan'!P26 -> 29800 | Q15: =SUM(D15:F15) -> 24365 | R15: =SUM(G15:I15) -> 34555 | S15: =SUM(J15:L15) -> 59732.5 | T15: =SUM(M14:O15) -> 69237.5 | U15: =SUM(D15:O15) -> 187890
C17: ='Business Plan'!C48 -> Approx net cashflow (sales FS only) | D17: ='Business Plan'!E48 -> -8254.1667 | E17: ='Business Plan'!F48 -> -16819.167 | F17: ='Business Plan'!G48 -> 11788.333 | G17: ='Business Plan'!H48 -> -5176.6667 | H17: ='Business Plan'!I48 -> -9819.1667 | I17: ='Business Plan'!J48 -> 14200.833 | J17: ='Business Plan'!K48 -> -4991.6667 | K17: ='Business Plan'!L48 -> 6988.3333 | ... O17: ='Business Plan'!P48 -> 20683.333 | Q17: =SUM(D17:F17) -> -13285 | R17: =SUM(G17:I17) -> -795 | S17: =SUM(J17:L17) -> 24382.5 | T17: =SUM(M16:O17) -> 33887.5 | U17: =SUM(D17:O17) -> 44190
C19: Commissions - Sales | D19: ='Business Plan'!E19 -> 7350 | E19: ='Business Plan'!F19 -> 8820 | F19: ='Business Plan'!G19 -> 10290 | G19: ='Business Plan'!H19 -> 8820 | H19: ='Business Plan'!I19 -> 10290 | I19: ='Business Plan'!J19 -> 17640 | J19: ='Business Plan'!K19 -> 10290 | K19: ='Business Plan'!L19 -> 11760 | ... O19: ='Business Plan'!P19 -> 8820 | Q19: =SUM(D19:F19) -> 26460 | R19: =SUM(G19:I19) -> 36750 | S19: =SUM(J19:L19) -> 38220 | T19: =SUM(M7:O19) -> 332635 | U19: =SUM(D19:O19) -> 147000 | W19: =SUM(F19:Q19) -> 157290
C20: Commissions - Integrations | D20: ='Business Plan'!E21 -> 0 | E20: ='Business Plan'!F21 -> 0 | F20: ='Business Plan'!G21 -> 0 | G20: ='Business Plan'!H21 -> 0 | H20: ='Business Plan'!I21 -> 0 | I20: ='Business Plan'!J21 -> 0 | J20: ='Business Plan'!K21 -> 0 | K20: ='Business Plan'!L21 -> 0 | ... O20: ='Business Plan'!P21 -> 0 | Q20: =SUM(D20:F20) -> 0 | R20: =SUM(G20:I20) -> 0 | S20: =SUM(J20:L20) -> 0 | T20: =SUM(M20:O20) -> 0 | U20: =SUM(D20:O20) -> 0 | W20: =SUM(F20:Q20) -> 0
C21: Onboardings | D21: ='Business Plan'!E22 -> 750 | E21: ='Business Plan'!F22 -> 750 | F21: ='Business Plan'!G22 -> 1500 | G21: ='Business Plan'!H22 -> 1500 | H21: ='Business Plan'!I22 -> 3000 | I21: ='Business Plan'!J22 -> 4500 | J21: ='Business Plan'!K22 -> 6000 | K21: ='Business Plan'!L22 -> 9000 | ... O21: ='Business Plan'!P22 -> 3000 | Q21: =SUM(D21:F21) -> 3000 | R21: =SUM(G21:I21) -> 9000 | S21: =SUM(J21:L21) -> 24000 | T21: =SUM(M20:O21) -> 21000 | U21: =SUM(D21:O21) -> 57000 | W21: =SUM(F21:Q21) -> 58500
C22: Bonus & Incentives | D22: ='Business Plan'!E20 -> 0 | E22: ='Business Plan'!F20 -> 0 | F22: ='Business Plan'!G20 -> 17200 | G22: ='Business Plan'!H20 -> 0 | H22: ='Business Plan'!I20 -> 0 | I22: ='Business Plan'!J20 -> 13550 | J22: ='Business Plan'!K20 -> 0 | K22: ='Business Plan'!L20 -> 0 | ... O22: ='Business Plan'!P20 -> 14550 | Q22: =SUM(D22:F22) -> 17200 | R22: =SUM(G22:I22) -> 13550 | S22: =SUM(J22:L22) -> 14050 | T22: =SUM(M19:O22) -> 81120 | U22: =SUM(D22:O22) -> 59350 | W22: =SUM(F22:Q22) -> 76550
C24: Headcount | D24: ='Business Plan'!E36 -> -14216.667 | E24: ='Business Plan'!F36 -> -14216.667 | F24: ='Business Plan'!G36 -> -14216.667 | G24: ='Business Plan'!H36 -> -14216.667 | H24: ='Business Plan'!I36 -> -14216.667 | I24: ='Business Plan'!J36 -> -14216.667 | J24: ='Business Plan'!K36 -> -14216.667 | K24: ='Business Plan'!L36 -> -14216.667 | ... O24: ='Business Plan'!P36 -> -14216.667 | Q24: =SUM(D24:F24) -> -42650 | R24: =SUM(G24:I24) -> -42650 | S24: =SUM(J24:L24) -> -42650 | T24: =SUM(M23:O24) -> -42650 | U24: =SUM(D24:O24) -> -170600 | W24: =SUM(F24:Q24) -> -184816.67
C25: Monthly Salary | D25: ='Business Plan'!E37 -> -14216.667 | E25: ='Business Plan'!F37 -> -14216.667 | F25: ='Business Plan'!G37 -> -14216.667 | G25: ='Business Plan'!H37 -> -14216.667 | H25: ='Business Plan'!I37 -> -14216.667 | I25: ='Business Plan'!J37 -> -14216.667 | J25: ='Business Plan'!K37 -> -14216.667 | K25: ='Business Plan'!L37 -> -14216.667 | ... O25: ='Business Plan'!P37 -> -14216.667 | Q25: =SUM(D25:F25) -> -42650 | R25: =SUM(G25:I25) -> -42650 | S25: =SUM(J25:L25) -> -42650 | T25: =SUM(M24:O25) -> -85300 | U25: =SUM(D25:O25) -> -170600 | W25: =SUM(F25:Q25) -> -184816.67
C26: Budget | D26: =-sumif('Demand Generation Plan'!$D$4:$D27,D3,'Demand Generation Plan'!$F$4:$F27) -> -1700 | E26: =-sumif('Demand Generation Plan'!$D$4:$D27,E3,'Demand Generation Plan'!$F$4:$F27) -> -11000 | F26: =-sumif('Demand Generation Plan'!$D$4:$D27,F3,'Demand Generation Plan'!$F$4:$F27) -> -1200 | G26: =-sumif('Demand Generation Plan'!$D$4:$D27,G3,'Demand Generation Plan'!$F$4:$F27) -> -1700 | H26: =-sumif('Demand Generation Plan'!$D$4:$D27,H3,'Demand Generation Plan'!$F$4:$F27) -> -8700 | I26: =-sumif('Demand Generation Plan'!$D$4:$D27,I3,'Demand Generation Plan'!$F$4:$F27) -> -1200 | J26: =-sumif('Demand Generation Plan'!$D$4:$D27,J3,'Demand Generation Plan'!$F$4:$F27) -> -9200 | K26: =-sumif('Demand Generation Plan'!$D$4:$D27,K3,'Demand Generation Plan'!$F$4:$F27) -> -1200 | ... O26: =-sumif('Demand Generation Plan'!$D$4:$D27,O3,'Demand Generation Plan'!$F$4:$F27) -> -1200 | Q26: =SUM(D26:F26) -> -13900 | R26: =SUM(G26:I26) -> -11600 | S26: =SUM(J26:L26) -> -11600 | T26: =SUM(M26:O26) -> -11600 | U26: =SUM(D26:O26) -> -48700 | W26: =SUM(F26:Q26) -> -49900
C27: Factorial Support | D27: ='Business Plan'!E38 -> 0 | E27: ='Business Plan'!F38 -> 0 | F27: ='Business Plan'!G38 -> 0 | G27: ='Business Plan'!H38 -> 0 | H27: ='Business Plan'!I38 -> 0 | I27: ='Business Plan'!J38 -> 0 | J27: ='Business Plan'!K38 -> 0 | K27: ='Business Plan'!L38 -> 0 | ... O27: ='Business Plan'!P38 -> 0 | Q27: =SUM(D27:F27) -> 0 | R27: =SUM(G27:I27) -> 0 | S27: =SUM(J27:L27) -> 0 | T27: =SUM(M25:O27) -> -54250 | U27: =SUM(D27:O27) -> 0 | W27: =SUM(F27:Q27) -> 0

Sheet Business Plan
D2: Total | E2: Q1 | H2: Q2 | K2: Q3 | N2: Q4 | R2: Q1 | S2: Q2 | T2: Q3 | U2: Q4
E3: January | F3: February | G3: March | H3: April | I3: May | J3: June | K3: July | L3: August | M3: September | N3: October | O3: November | P3: December
C4: Required Demos # | D4: =SUM(E4:P4) -> 133 | E4: =INT(E9/E5) -> 5 | F4: =INT(F9/F5) -> 5 | G4: =INT(G9/G5) -> 11 | H4: =INT(H9/H5) -> 5 | I4: =INT(I9/I5) -> 11 | J4: =INT(J9/J5) -> 16 | K4: =INT(K9/K5) -> 11 | L4: =INT(L9/L5) -> 16 | ... P4: =INT(P9/P5) -> 5 | R4: =SUM(E4:G4) -> 21 | S4: =SUM(H4:J4) -> 32 | T4: =SUM(K4:M4) -> 43 | U4: =SUM(N3:P4) -> 37
C5: % Demo to Customer | E5: 0.18 | F5: 0.18 | G5: 0.18 | H5: 0.18 | I5: 0.18 | J5: 0.18 | K5: 0.18 | L5: 0.18 | M5: 0.18 | N5: 0.18 | O5: 0.18 | P5: =O5 -> 0.18 | R5: =R9/R4 -> 0.19047619 | S5: =S9/S4 -> 0.1875 | T5: =T9/T4 -> 0.18604651 | U5: =U9/U4 -> 0.18918919
C6: Planned Demos | D6: =SUM(E6:P6) -> 220 | E6: =SUMIF(E50,"=" & 'Business Plan'!E3,E51) -> 10 | F6: =SUMIF(F50,"=" & 'Business Plan'!F3,F51) -> 11 | G6: =SUMIF(G50,"=" & 'Business Plan'!G3,G51) -> 34 | H6: =SUMIF(H50,"=" & 'Business Plan'!H3,H51) -> 12 | I6: =SUMIF(I50,"=" & 'Business Plan'!I3,I51) -> 22 | J6: =SUMIF(J50,"=" & 'Business Plan'!J3,J51) -> 17 | K6: =SUMIF(K50,"=" & 'Business Plan'!K3,K51) -> 23 | L6: =SUMIF(L50,"=" & 'Business Plan'!L3,L51) -> 18 | ... P6: =SUMIF(P50,"=" & 'Business Plan'!P3,P51) -> 14 | R6: =SUM(E6:G6) -> 55 | S6: =SUM(H6:J6) -> 51 | T6: =SUM(K6:M6) -> 57 | U6: =SUM(N5:P6) -> 57.54
C7: Action Review | D7: =IF(SUM(E8:P8)=12,"CORRECT","REVIEW DATA") -> REVIEW DATA | E7: =IF((SUMIF(E50,"=" & 'Business Plan'!E3,E51))>=E4, "CORRECT", CONCATENATE(E$4-(SUMIF(E50,"=" & 'Business Plan'!E3,E51))," Demos Missing in Plan")) -> CORRECT | F7: =IF((SUMIF(F50,"=" & 'Business Plan'!F3,F51))>=F4, "CORRECT", CONCATENATE(F$4-(SUMIF(F50,"=" & 'Business Plan'!F3,F51))," Demos Missing in Plan")) -> CORRECT | G7: =IF((SUMIF(G50,"=" & 'Business Plan'!G3,G51))>=G4, "CORRECT", CONCATENATE(G$4-(SUMIF(G50,"=" & 'Business Plan'!G3,G51))," Demos Missing in Plan")) -> CORRECT | H7: =IF((SUMIF(H50,"=" & 'Business Plan'!H3,H51))>=H4, "CORRECT", CONCATENATE(H$4-(SUMIF(H50,"=" & 'Business Plan'!H3,H51))," Demos Missing in Plan")) -> CORRECT | I7: =IF((SUMIF(I50,"=" & 'Business Plan'!I3,I51))>=I4, "CORRECT", CONCATENATE(I$4-(SUMIF(I50,"=" & 'Business Plan'!I3,I51))," Demos Missing in Plan")) -> CORRECT | J7: =IF((SUMIF(J50,"=" & 'Business Plan'!J3,J51))>=J4, "CORRECT", CONCATENATE(J$4-(SUMIF(J50,"=" & 'Business Plan'!J3,J51))," Demos Missing in Plan")) -> CORRECT | K7: =IF((SUMIF(K50,"=" & 'Business Plan'!K3,K51))>=K4, "CORRECT", CONCATENATE(K$4-(SUMIF(K50,"=" & 'Business Plan'!K3,K51))," Demos Missing in Plan")) -> CORRECT | L7: =IF((SUMIF(L50,"=" & 'Business Plan'!L3,L51))>=L4, "CORRECT", CONCATENATE(L$4-(SUMIF(L50,"=" & 'Business Plan'!L3,L51))," Demos Missing in Plan")) -> CORRECT | ... P7: =IF((SUMIF(P50,"=" & 'Business Plan'!P3,P51))>=P4, "CORRECT", CONCATENATE(P$4-(SUMIF(P50,"=" & 'Business Plan'!P3,P51))," Demos Missing in Plan")) -> CORRECT
E8: =IF(E7="CORRECT","1","0") -> 1 | F8: =IF(F7="CORRECT","1","0") -> 1 | G8: =IF(G7="CORRECT","1","0") -> 1 | H8: =IF(H7="CORRECT","1","0") -> 1 | I8: =IF(I7="CORRECT","1","0") -> 1 | J8: =IF(J7="CORRECT","1","0") -> 1 | K8: =IF(K7="CORRECT","1","0") -> 1 | L8: =IF(L7="CORRECT","1","0") -> 1 | ... P8: =IF(P7="CORRECT","1","0") -> 1
C9: Won Customers # | D9: =SUM(E9:P9) -> 25 | E9: =INT(E12/E14) -> 1 | F9: =INT(F12/F14) -> 1 | G9: =INT(G12/G14) -> 2 | H9: =INT(H12/H14) -> 1 | I9: =INT(I12/I14) -> 2 | J9: =INT(J12/J14) -> 3 | K9: =INT(K12/K14) -> 2 | L9: 3 | M9: =INT(M12/M14) -> 3 | N9: =INT(N12/N14) -> 3 | O9: =INT(O12/O14) -> 3 | P9: 1 | R9: =SUM(E9:G9) -> 4 | S9: =SUM(H9:J9) -> 6 | T9: =SUM(K9:M9) -> 8 | U9: =SUM(N8:P9) -> 7
C10: Quality Check | D10: =CONCATENATE(IFS( D9/'Partnership Info'!D18 < 0.1, "<10%", D9/'Partnership Info'!D18 < 0.25, "10-25%", D9/'Partnership Info'!D18 < 0.45, "25-45%", D9/'Partnership Info'!D18 < 0.65, "45-65%", D9/'Partnership Info'!D18 < 0.85, "65-85%", TRUE, ">85%" )," of your customer base") -> <10% of your customer base
C12: Won MRR | D12: 35000 | E12: =$D$12*E13 -> 1750 | F12: =$D$12*F13 -> 2100 | G12: =$D$12*G13 -> 2450 | H12: =$D$12*H13 -> 2100 | I12: =$D$12*I13 -> 2450 | J12: =$D$12*J13 -> 4200 | K12: =$D$12*K13 -> 2450 | L12: =$D$12*L13 -> 2800 | ... P12: =$D$12*P13 -> 2100 | R12: =SUM(E12:G12) -> 6300 | S12: =SUM(H12:J12) -> 8750 | T12: =SUM(K12:M12) -> 9100 | U12: =SUM(N11:P12) -> 10850
C13: Seasonality | D13: =SUM(E13:P13) -> 1 | E13: 0.05 | F13: 0.06 | G13: 0.07 | H13: 0.06 | I13: 0.07 | J13: 0.12 | K13: 0.07 | L13: 0.08 | M13: 0.11 | N13: 0.12 | O13: 0.13 | P13: 0.06
C14: ARPU | D14: 1200 | E14: 1200 | F14: =E14 -> 1200 | G14: =F14 -> 1200 | H14: =G14 -> 1200 | I14: =H14 -> 1200 | J14: =I14 -> 1200 | K14: =J14 -> 1200 | L14: =K14 -> 1200 | M14: =L14 -> 1200 | ... P14: =O14 -> 1200 | R14: =R12/R9 -> 1575 | S14: =S12/S9 -> 1458.3333 | T14: =T12/T9 -> 1137.5 | U14: =U12/U9 -> 1550
C15: Won ARR | D15: =D12*12 -> 420000 | E15: =E12*12 -> 21000 | F15: =F12*12 -> 25200 | G15: =G12*12 -> 29400 | H15: =H12*12 -> 25200 | I15: =I12*12 -> 29400 | J15: =J12*12 -> 50400 | K15: =K12*12 -> 29400 | ... P15: =P12*12 -> 25200 | R15: =SUM(E15:G15) -> 75600 | S15: =SUM(H15:J15) -> 105000 | T15: =SUM(K15:M15) -> 109200 | U15: =SUM(N14:P15) -> 133800
C16: Won ARR (agg) | E16: =sum($E12:E12)*12 -> 21000 | F16: =sum($E12:F12)*12 -> 46200 | G16: =sum($E12:G12)*12 -> 75600 | H16: =sum($E12:H12)*12 -> 100800 | I16: =sum($E12:I12)*12 -> 130200 | J16: =sum($E12:J12)*12 -> 180600 | K16: =sum($E12:K12)*12 -> 210000 | L16: =sum($E12:L12)*12 -> 243600 | ... P16: =sum($E12:P12)*12 -> 420000 | R16: =R12 -> 6300 | S16: =R16+S12 -> 15050 | T16: =S16+T12 -> 24150 | U16: =T16+U12 -> 35000
C18: Commissions Total | D18: =SUM(E18:P18) -> 263350 | E18: =sum(E19:E22) -> 8100 | F18: =sum(F19:F22) -> 9570 | G18: =sum(G19:G22) -> 28990 | H18: =sum(H19:H22) -> 10320 | I18: =sum(I19:I22) -> 13290 | J18: =sum(J19:J22) -> 35690 | K18: =sum(K19:K22) -> 16290 | L18: =sum(L19:L22) -> 20760 | ... P18: =sum(P19:P22) -> 26370 | R18: =SUM(E18:G18) -> 46660 | S18: =SUM(H18:J18) -> 59300 | T18: =SUM(K18:M18) -> 76270 | U18: =SUM(N17:P18) -> 81120
C19: Commissions - Sales | D19: =SUM(E19:P19) -> 147000 | E19: ='Partnership Info'!$D$11*E15 -> 7350 | F19: ='Partnership Info'!$D$11*F15 -> 8820 | G19: ='Partnership Info'!$D$11*G15 -> 10290 | H19: ='Partnership Info'!$D$11*H15 -> 8820 | I19: ='Partnership Info'!$D$11*I15 -> 10290 | J19: ='Partnership Info'!$D$11*J15 -> 17640 | K19: ='Partnership Info'!$D$11*K15 -> 10290 | L19: ='Partnership Info'!$D$11*L15 -> 11760 | ... P19: ='Partnership Info'!$D$11*P15 -> 8820 | R19: =SUM(E19:G19) -> 26460 | S19: =SUM(H19:J19) -> 36750 | T19: =SUM(K19:M19) -> 38220 | U19: =SUM(N18:P19) -> 126690
C20: Bonus & Incentives | D20: =SUM(E20:P20) -> 59350 | E20: =SUMIF('B&I'!$G$3:$G58,E3,'B&I'!$F$3:$F58) -> 0 | F20: =SUMIF('B&I'!$G$3:$G58,F3,'B&I'!$F$3:$F58) -> 0 | G20: =SUMIF('B&I'!$G$3:$G58,G3,'B&I'!$F$3:$F58) -> 17200 | H20: =SUMIF('B&I'!$G$3:$G58,H3,'B&I'!$F$3:$F58) -> 0 | I20: =SUMIF('B&I'!$G$3:$G58,I3,'B&I'!$F$3:$F58) -> 0 | J20: =SUMIF('B&I'!$G$3:$G58,J3,'B&I'!$F$3:$F58) -> 13550 | K20: =SUMIF('B&I'!$G$3:$G58,K3,'B&I'!$F$3:$F58) -> 0 | L20: =SUMIF('B&I'!$G$3:$G58,L3,'B&I'!$F$3:$F58) -> 0 | ... P20: =SUMIF('B&I'!$G$3:$G58,P3,'B&I'!$F$3:$F58) -> 14550 | R20: =SUM(E20:G20) -> 17200 | S20: =SUM(H20:J20) -> 13550 | T20: =SUM(K20:M20) -> 14050 | U20: =SUM(N19:P20) -> 60120
C21: Own Integrations | D21: =SUM(E21:P21) -> 0 | E21: =E9*'Partnership Info'!$D$16 -> 0 | F21: =F9*'Partnership Info'!$D$16 -> 0 | G21: =G9*'Partnership Info'!$D$16 -> 0 | H21: =H9*'Partnership Info'!$D$16 -> 0 | I21: =I9*'Partnership Info'!$D$16 -> 0 | J21: =J9*'Partnership Info'!$D$16 -> 0 | K21: =K9*'Partnership Info'!$D$16 -> 0 | L21: =L9*'Partnership Info'!$D$16 -> 0 | ... P21: =P9*'Partnership Info'!$D$16 -> 0 | R21: =SUM(E21:G21) -> 0 | S21: =SUM(H21:J21) -> 0 | T21: =SUM(K21:M21) -> 0 | U21: =SUM(N20:P21) -> 14550
C22: Onboardings | D22: =SUM(E22:P22) -> 57000 | E22: =IF('Partnership Info'!$D$13=TRUE,E9*'Partnership Info'!$D$14*E23,"") -> 750 | F22: =IF('Partnership Info'!$D$13=TRUE,F9*'Partnership Info'!$D$14*F23,"") -> 750 | G22: =IF('Partnership Info'!$D$13=TRUE,G9*'Partnership Info'!$D$14*G23,"") -> 1500 | H22: =IF('Partnership Info'!$D$13=TRUE,H9*'Partnership Info'!$D$14*H23,"") -> 1500 | I22: =IF('Partnership Info'!$D$13=TRUE,I9*'Partnership Info'!$D$14*I23,"") -> 3000 | J22: =IF('Partnership Info'!$D$13=TRUE,J9*'Partnership Info'!$D$14*J23,"") -> 4500 | K22: =IF('Partnership Info'!$D$13=TRUE,K9*'Partnership Info'!$D$14*K23,"") -> 6000 | L22: =IF('Partnership Info'!$D$13=TRUE,L9*'Partnership Info'!$D$14*L23,"") -> 9000 | ... P22: =IF('Partnership Info'!$D$13=TRUE,P9*'Partnership Info'!$D$14*P23,"") -> 3000 | R22: =SUM(E22:G22) -> 3000 | S22: =SUM(H22:J22) -> 9000 | T22: =SUM(K22:M22) -> 24000 | U22: =SUM(N21:P22) -> 21000
C23: Onboarding % | E23: 0.25 | F23: 0.25 | G23: 0.25 | H23: 0.5 | I23: 0.5 | J23: 0.5 | K23: 1 | L23: 1 | M23: 1 | N23: 1 | O23: 1 | P23: 1
C24: Commissions Total (agg) | D24: =P24 -> 263350 | E24: =E18 -> 8100 | F24: =F18+E24 -> 17670 | G24: =G18+F24 -> 46660 | H24: =H18+G24 -> 56980 | I24: =I18+H24 -> 70270 | J24: =J18+I24 -> 105960 | K24: =K18+J24 -> 122250 | L24: =L18+K24 -> 143010 | M24: =M18+L24 -> 182230 | ... P24: =P18+O24 -> 263350 | R24: =R18 -> 46660 | S24: =R24+S18 -> 105960 | T24: =S24+T18 -> 182230 | U24: =T24+U18 -> 263350
C26: Commissions cashflow (new MRR only) | D26: =SUM(D27:D30) -> 187890 | E26: =Sum(E28:E30) -> 1362.5 | F26: =Sum(F28:F30) -> 2097.5 | G26: =Sum(G28:G30) -> 20905 | H26: =Sum(H28:H30) -> 4440 | I26: =Sum(I28:I30) -> 6797.5 | J26: =Sum(J28:J30) -> 23317.5 | K26: =Sum(K28:K30) -> 12125 | L26: =Sum(L28:L30) -> 16105 | ... P26: =Sum(P28:P30) -> 29800 | R26: =SUM(E26:G26) -> 24365 | S26: =SUM(H26:J26) -> 34555 | T26: =SUM(K26:M26) -> 59732.5 | U26: =SUM(N26:P26) -> 69237.5
C27: Commissions - Sales new | E27: =E12*'Partnership Info'!$D11 -> 612.5 | F27: =F12*'Partnership Info'!$D11 -> 735 | G27: =G12*'Partnership Info'!$D11 -> 857.5 | H27: =H12*'Partnership Info'!$D11 -> 735 | I27: =I12*'Partnership Info'!$D11 -> 857.5 | J27: =J12*'Partnership Info'!$D11 -> 1470 | K27: =K12*'Partnership Info'!$D11 -> 857.5 | L27: =L12*'Partnership Info'!$D11 -> 980 | ... P27: =P12*'Partnership Info'!$D11 -> 735
C28: Commissions - Sales agg | D28: =SUM(E28:P28) -> 71540 | E28: =SUM(E27) -> 612.5 | F28: =E28+F27 -> 1347.5 | G28: =F28+G27 -> 2205 | H28: =G28+H27 -> 2940 | I28: =H28+I27 -> 3797.5 | J28: =I28+J27 -> 5267.5 | K28: =J28+K27 -> 6125 | L28: =K28+L27 -> 7105 | M28: =L28+M27 -> 8452.5 | ... P28: =O28+P27 -> 12250 | R28: =SUM(E28:G28) -> 4165 | S28: =SUM(H28:J28) -> 12005 | T28: =SUM(K28:M28) -> 21682.5 | U28: =SUM(N27:P28) -> 37485
C29: B&I | D29: =SUM(E29:P29) -> 59350 | E29: =E20 -> 0 | F29: =F20 -> 0 | G29: =G20 -> 17200 | H29: =H20 -> 0 | I29: =I20 -> 0 | J29: =J20 -> 13550 | K29: =K20 -> 0 | L29: =L20 -> 0 | ... P29: =P20 -> 14550 | R29: =SUM(E29:G29) -> 17200 | S29: =SUM(H29:J29) -> 13550 | T29: =SUM(K29:M29) -> 14050 | U29: =SUM(N28:P29) -> 48237.5
C30: Onboardings | D30: =SUM(E30:P30) -> 57000 | E30: =E22 -> 750 | F30: =F22 -> 750 | G30: =G22 -> 1500 | H30: =H22 -> 1500 | I30: =I22 -> 3000 | J30: =J22 -> 4500 | K30: =K22 -> 6000 | L30: =L22 -> 9000 | ... P30: =P22 -> 3000 | R30: =SUM(E30:G30) -> 3000 | S30: =SUM(H30:J30) -> 9000 | T30: =SUM(K30:M30) -> 24000 | U30: =SUM(N29:P30) -> 35550
C32: Demand Generation Plan
C33: Actions # | D33: =SUM(E33:P33) -> 32 | E33: =COUNTIF('Demand Generation Plan'!$D$4:$D58,E3) -> 3 | F33: =COUNTIF('Demand Generation Plan'!$D$4:$D58,F3) -> 3 | G33: =COUNTIF('Demand Generation Plan'!$D$4:$D58,G3) -> 2 | H33: =COUNTIF('Demand Generation Plan'!$D$4:$D58,H3) -> 3 | I33: =COUNTIF('Demand Generation Plan'!$D$4:$D58,I3) -> 3 | J33: =COUNTIF('Demand Generation Plan'!$D$4:$D58,J3) -> 2 | K33: =COUNTIF('Demand Generation Plan'!$D$4:$D58,K3) -> 4 | L33: =COUNTIF('Demand Generation Plan'!$D$4:$D58,L3) -> 2 | ... P33: =COUNTIF('Demand Generation Plan'!$D$4:$D58,P3) -> 2 | R33: =SUM(E33:G33) -> 8 | S33: =SUM(H33:J33) -> 8 | T33: =SUM(K33:M33) -> 8 | U33: =SUM(N32:P33) -> 8
C34: Budget | D34: =SUM(E34:P34) -> -48700 | E34: =-sumif('Demand Generation Plan'!$D$4:$D58,E3,'Demand Generation Plan'!$F$4:$F58) -> -1700 | F34: =-sumif('Demand Generation Plan'!$D$4:$D58,F3,'Demand Generation Plan'!$F$4:$F58) -> -11000 | G34: =-sumif('Demand Generation Plan'!$D$4:$D58,G3,'Demand Generation Plan'!$F$4:$F58) -> -1200 | H34: =-sumif('Demand Generation Plan'!$D$4:$D58,H3,'Demand Generation Plan'!$F$4:$F58) -> -1700 | I34: =-sumif('Demand Generation Plan'!$D$4:$D58,I3,'Demand Generation Plan'!$F$4:$F58) -> -8700 | J34: =-sumif('Demand Generation Plan'!$D$4:$D58,J3,'Demand Generation Plan'!$F$4:$F58) -> -1200 | K34: =-sumif('Demand Generation Plan'!$D$4:$D58,K3,'Demand Generation Plan'!$F$4:$F58) -> -9200 | L34: =-sumif('Demand Generation Plan'!$D$4:$D58,L3,'Demand Generation Plan'!$F$4:$F58) -> -1200 | ... P34: =-sumif('Demand Generation Plan'!$D$4:$D58,P3,'Demand Generation Plan'!$F$4:$F58) -> -1200 | R34: =SUM(E34:G34) -> -13900 | S34: =SUM(H34:J34) -> -11600 | T34: =SUM(K34:M34) -> -11600 | U34: =SUM(N33:P34) -> -11592
C36: Headcount | D36: =D37+D38 -> -170600 | E36: =E37+E38 -> -14216.667 | F36: =F37+F38 -> -14216.667 | G36: =G37+G38 -> -14216.667 | H36: =H37+H38 -> -14216.667 | I36: =I37+I38 -> -14216.667 | J36: =J37+J38 -> -14216.667 | K36: =K37+K38 -> -14216.667 | ... P36: =P37+P38 -> -14216.667 | R36: =SUM(E36:G36) -> -42650 | S36: =SUM(H36:J36) -> -42650 | T36: =SUM(K36:M36) -> -42650 | U36: =SUM(N36:P36) -> -42650
C37: Salary | D37: =SUM(E37:P37) -> -170600 | E37: =Headcount!G4 -> -14216.667 | F37: =Headcount!H4 -> -14216.667 | G37: =Headcount!I4 -> -14216.667 | H37: =Headcount!J4 -> -14216.667 | I37: =Headcount!K4 -> -14216.667 | J37: =Headcount!L4 -> -14216.667 | K37: =Headcount!M4 -> -14216.667 | L37: =Headcount!N4 -> -14216.667 | ... P37: =Headcount!R4 -> -14216.667 | R37: =SUM(E37:G37) -> -42650 | S37: =SUM(H37:J37) -> -42650 | T37: =SUM(K37:M37) -> -42650 | U37: =SUM(N37:P37) -> -42650
C38: Factorial Support | D38: =SUM(E38:P38) -> 0 | E38: =Headcount!G5 -> 0 | F38: =Headcount!H5 -> 0 | G38: =Headcount!I5 -> 0 | H38: =Headcount!J5 -> 0 | I38: =Headcount!K5 -> 0 | J38: =Headcount!L5 -> 0 | K38: =Headcount!M5 -> 0 | L38: =Headcount!N5 -> 0 | ... P38: =Headcount!R5 -> 0 | R38: =SUM(E38:G38) -> 0 | S38: =SUM(H38:J38) -> 0 | T38: =SUM(K38:M38) -> 0 | U38: =SUM(N37:P38) -> -42650
C39: Fixed salary | D39: =SUM(E39:P39) -> -95000 | E39: =-14000/7*1.25-25000*1.25/12-27000*1.25/12 -> -7916.6667 | F39: =-14000/7*1.25-25000*1.25/12-27000*1.25/12 -> -7916.6667 | G39: =-14000/7*1.25-25000*1.25/12-27000*1.25/12 -> -7916.6667 | H39: =-14000/7*1.25-25000*1.25/12-27000*1.25/12 -> -7916.6667 | I39: =-14000/7*1.25-25000*1.25/12-27000*1.25/12 -> -7916.6667 | J39: =-14000/7*1.25-25000*1.25/12-27000*1.25/12 -> -7916.6667 | K39: =-14000/7*1.25-25000*1.25/12-27000*1.25/12 -> -7916.6667 | L39: =-14000/7*1.25-25000*1.25/12-27000*1.25/12 -> -7916.6667 | ... P39: =-14000/7*1.25-25000*1.25/12-27000*1.25/12 -> -7916.6667 | R39: =SUM(E39:G39) -> -23750 | S39: =SUM(H39:J39) -> -23750 | T39: =SUM(K39:M39) -> -23750 | U39: =SUM(N39:P39) -> -23750
C40: Variable salary | D40: =SUM(E40:P40) -> -75600 | E40: =E37-E39 -> -6300 | F40: =F37-F39 -> -6300 | G40: =G37-G39 -> -6300 | H40: =H37-H39 -> -6300 | I40: =I37-I39 -> -6300 | J40: =J37-J39 -> -6300 | K40: =K37-K39 -> -6300 | L40: =L37-L39 -> -6300 | ... P40: =P37-P39 -> -6300 | R40: =SUM(E40:G40) -> -18900 | S40: =SUM(H40:J40) -> -18900 | T40: =SUM(K40:M40) -> -18900 | U40: =SUM(N40:P40) -> -18900
C42: Total Commissions + Incentives | D42: =SUM(E42:P42) -> 263350 | E42: =E18 -> 8100 | F42: =F18 -> 9570 | G42: =G18 -> 28990 | H42: =H18 -> 10320 | I42: =I18 -> 13290 | J42: =J18 -> 35690 | K42: =K18 -> 16290 | L42: =L18 -> 20760 | ... P42: =P18 -> 26370 | R42: =SUM(E42:G42) -> 46660 | S42: =SUM(H42:J42) -> 59300 | T42: =SUM(K42:M42) -> 76270 | U42: =SUM(N41:P42) -> 81120
C44: Total Invested | D44: =SUM(E44:P44) -> -219300 | E44: =E36+E34 -> -15916.667 | F44: =F36+F34 -> -25216.667 | G44: =G36+G34 -> -15416.667 | H44: =H36+H34 -> -15916.667 | I44: =I36+I34 -> -22916.667 | J44: =J36+J34 -> -15416.667 | K44: =K36+K34 -> -23416.667 | L44: =L36+L34 -> -15416.667 | ... P44: =P36+P34 -> -15416.667 | R44: =SUM(E44:G44) -> -56550 | S44: =SUM(H44:J44) -> -54250 | T44: =SUM(K44:M44) -> -54250 | U44: =SUM(N43:P44) -> -54250
C46: Total Balance (12-month P&L) | D46: =SUM(E46:P46) -> 44050 | E46: =E42+E44 -> -7816.6667 | F46: =F42+F44 -> -15646.667 | G46: =G42+G44 -> 13573.333 | H46: =H42+H44 -> -5596.6667 | I46: =I42+I44 -> -9626.6667 | J46: =J42+J44 -> 20273.333 | K46: =K42+K44 -> -7126.6667 | L46: =L42+L44 -> 5343.3333 | ... P46: =P42+P44 -> 10953.333 | R46: =SUM(E46:G46) -> -9890 | S46: =SUM(H46:J46) -> 5050 | T46: =SUM(K46:M46) -> 22020 | U46: =SUM(N45:P46) -> 26870
C48: Approx net cashflow (sales FS only) | D48: =SUM(E48:P48) -> 44190 | E48: =E26+E34+E39 -> -8254.1667 | F48: =F26+F34+F39 -> -16819.167 | G48: =G26+G34+G39 -> 11788.333 | H48: =H26+H34+H39 -> -5176.6667 | I48: =I26+I34+I39 -> -9819.1667 | J48: =J26+J34+J39 -> 14200.833 | K48: =K26+K34+K39 -> -4991.6667 | L48: =L26+L34+L39 -> 6988.3333 | ... P48: =P26+P34+P39 -> 20683.333 | R48: =SUM(E48:G48) -> -13285 | S48: =SUM(H48:J48) -> -795 | T48: =SUM(K48:M48) -> 24382.5 | U48: =SUM(N47:P48) -> 33887.5
C49: DEMGEN PLAN CHECK | E49: 1 | F49: 2 | G49: 3 | H49: 4 | I49: 5 | J49: 6 | K49: 7 | L49: 8 | M49: 9 | N49: 10 | O49: 11 | P49: 12
E50: January | F50: February | G50: March | H50: April | I50: May | J50: June | K50: July | L50: August | M50: September | N50: October | O50: November | P50: December
...

Sheet Demand Generation Plan
H1: 0 | I1: 1 | J1: 2 | M1: 0 | N1: 1 | O1: 2
C2: Planned Actions | L2: Results | U2: Analysis
B3: Action Name | C3: Quarter | D3: Month | E3: Type of action | F3: Planned Cost | G3: Demos Goal | H3: M0 | I3: M1 | J3: M2 | K3: Cost per demo | L3: Demos Actual | M3: M0 | N3: M1 | O3: M2 | P3: Leads Actual | Q3: Clients Won | R3: Total Cost | S3: Partner Actual Cost | T3: MRR won | U3: ROI (on ARR) | V3: % Lead to Demo | W3: % Demo to Won | X3: CAC | Y3: Cost per Demo
A4: =iferror(DATEVALUE(D4 & " 1"),"") -> 45658 | B4: Outbound Q1 | C4: =IF(D4="","", IF(A4<DATE(2025, 4, 1),"Q1",if(A4<DATE(2025, 7, 1),"Q2",IF(A4<DATE(2025, 10, 1),"Q3","Q4")))) -> Q1 | D4: January | E4: Outbound Actions | F4: 500 | G4: 9 | H4: 3 | I4: 3 | J4: 3 | K4: =IFERROR(F4/G4,"") -> 55.555556 | L4: =SUM(M4:O4) -> 0 | M4: 0 | N4: 0 | O4: 0 | P4: 0 | Q4: 0 | R4: 0 | T4: 0 | U4: =if(T4<=0,"",((T4*12)-R4)/R4) | V4: =iferror(L4/P4,"") | W4: =iferror(Q4/L4,"") | X4: =iferror(R4/Q4,"") | Y4: =iferror(R4/L4,"")
A5: =iferror(DATEVALUE(D5 & " 1"),"") -> 45748 | B5: Outbound Q2 | C5: =IF(D5="","", IF(A5<DATE(2025, 4, 1),"Q1",if(A5<DATE(2025, 7, 1),"Q2",IF(A5<DATE(2025, 10, 1),"Q3","Q4")))) -> Q2 | D5: April | E5: Outbound Actions | F5: 500 | G5: =SUM(H5:J5) -> 12 | H5: 4 | I5: 4 | J5: 4 | K5: =IFERROR(F5/G5,"") -> 41.666667 | L5: =SUM(M5:O5) -> 0 | U5: =if(T5<=0,"",((T5*12)-F5)/F5) | V5: =iferror(L5/P5,"") | W5: =iferror(Q5/L5,"") | X5: =iferror(R5/Q5,"") | Y5: =iferror(R5/L5,"")
A6: =iferror(DATEVALUE(D6 & " 1"),"") -> 45839 | B6: Outbound Q3 | C6: =IF(D6="","", IF(A6<DATE(2025, 4, 1),"Q1",if(A6<DATE(2025, 7, 1),"Q2",IF(A6<DATE(2025, 10, 1),"Q3","Q4")))) -> Q3 | D6: July | E6: Outbound Actions | F6: 500 | G6: =SUM(H6:J6) -> 15 | H6: 5 | I6: 5 | J6: 5 | K6: =IFERROR(F6/G6,"") -> 33.333333 | L6: =SUM(M6:O6) -> 0 | U6: =if(T6<=0,"",((T6*12)-F6)/F6) | V6: =iferror(L6/P6,"") | W6: =iferror(Q6/L6,"") | X6: =iferror(R6/Q6,"") | Y6: =iferror(R6/L6,"")
A7: =iferror(DATEVALUE(D7 & " 1"),"") -> 45931 | B7: Outbound Q4 | C7: =IF(D7="","", IF(A7<DATE(2025, 4, 1),"Q1",if(A7<DATE(2025, 7, 1),"Q2",IF(A7<DATE(2025, 10, 1),"Q3","Q4")))) -> Q4 | D7: October | E7: Outbound Actions | F7: 500 | G7: =SUM(H7:J7) -> 18 | H7: 6 | I7: 6 | J7: 6 | K7: =IFERROR(F7/G7,"") -> 27.777778 | L7: =SUM(M7:O7) -> 0 | U7: =if(T7<=0,"",((T7*12)-F7)/F7) | V7: =iferror(L7/P7,"") | W7: =iferror(Q7/L7,"") | X7: =iferror(R7/Q7,"") | Y7: =iferror(R7/L7,"")
A8: =iferror(DATEVALUE(D8 & " 1"),"") -> 45658 | B8: Webinar | C8: =IF(D8="","", IF(A8<DATE(2025, 4, 1),"Q1",if(A8<DATE(2025, 7, 1),"Q2",IF(A8<DATE(2025, 10, 1),"Q3","Q4")))) -> Q1 | D8: January | E8: Webinar | F8: 200 | G8: 5 | H8: 5 | K8: =IFERROR(F8/G8,"") -> 40 | L8: =SUM(M8:O8) -> 0 | U8: =if(T8<=0,"",((T8*12)-F8)/F8) | V8: =iferror(L8/P8,"") | W8: =iferror(Q8/L8,"") | X8: =iferror(R8/Q8,"") | Y8: =iferror(R8/L8,"")
A9: =iferror(DATEVALUE(D9 & " 1"),"") -> 45689 | B9: Webinar | C9: =IF(D9="","", IF(A9<DATE(2025, 4, 1),"Q1",if(A9<DATE(2025, 7, 1),"Q2",IF(A9<DATE(2025, 10, 1),"Q3","Q4")))) -> Q1 | D9: February | K9: =IFERROR(F9/G9,"") | L9: =SUM(M9:O9) -> 0 | U9: =if(T9<=0,"",((T9*12)-F9)/F9) | V9: =iferror(L9/P9,"") | W9: =iferror(Q9/L9,"") | X9: =iferror(R9/Q9,"") | Y9: =iferror(R9/L9,"")
A10: =iferror(DATEVALUE(D10 & " 1"),"") -> 45717 | B10: Webinar | C10: =IF(D10="","", IF(A10<DATE(2025, 4, 1),"Q1",if(A10<DATE(2025, 7, 1),"Q2",IF(A10<DATE(2025, 10, 1),"Q3","Q4")))) -> Q1 | D10: March | E10: Webinar | F10: 200 | G10: 2 | H10: 2 | K10: =IFERROR(F10/G10,"") -> 100 | L10: =SUM(M10:O10) -> 0 | U10: =if(T10<=0,"",((T10*12)-F10)/F10) | V10: =iferror(L10/P10,"") | W10: =iferror(Q10/L10,"") | X10: =iferror(R10/Q10,"") | Y10: =iferror(R10/L10,"")
A11: =iferror(DATEVALUE(D11 & " 1"),"") -> 45748 | B11: Webinar | C11: =IF(D11="","", IF(A11<DATE(2025, 4, 1),"Q1",if(A11<DATE(2025, 7, 1),"Q2",IF(A11<DATE(2025, 10, 1),"Q3","Q4")))) -> Q2 | D11: April | E11: Webinar | F11: 200 | G11: 3 | H11: 3 | K11: =IFERROR(F11/G11,"") -> 66.666667 | L11: =SUM(M11:O11) -> 0 | U11: =if(T11<=0,"",((T11*12)-F11)/F11) | V11: =iferror(L11/P11,"") | W11: =iferror(Q11/L11,"") | X11: =iferror(R11/Q11,"") | Y11: =iferror(R11/L11,"")
A12: =iferror(DATEVALUE(D12 & " 1"),"") -> 45778 | B12: Webinar | C12: =IF(D12="","", IF(A12<DATE(2025, 4, 1),"Q1",if(A12<DATE(2025, 7, 1),"Q2",IF(A12<DATE(2025, 10, 1),"Q3","Q4")))) -> Q2 | D12: May | E12: Webinar | F12: 200 | G12: 3 | H12: 3 | K12: =IFERROR(F12/G12,"") -> 66.666667 | L12: =SUM(M12:O12) -> 0 | U12: =if(T12<=0,"",((T12*12)-F12)/F12) | V12: =iferror(L12/P12,"") | W12: =iferror(Q12/L12,"") | X12: =iferror(R12/Q12,"") | Y12: =iferror(R12/L12,"")
A13: =iferror(DATEVALUE(D13 & " 1"),"") -> 45809 | B13: Webinar | C13: =IF(D13="","", IF(A13<DATE(2025, 4, 1),"Q1",if(A13<DATE(2025, 7, 1),"Q2",IF(A13<DATE(2025, 10, 1),"Q3","Q4")))) -> Q2 | D13: June | E13: Webinar | F13: 200 | G13: 3 | H13: 3 | K13: =IFERROR(F13/G13,"") -> 66.666667 | L13: =SUM(M13:O13) -> 0 | U13: =if(T13<=0,"",((T13*12)-F13)/F13) | V13: =iferror(L13/P13,"") | W13: =iferror(Q13/L13,"") | X13: =iferror(R13/Q13,"") | Y13: =iferror(R13/L13,"")
A14: =iferror(DATEVALUE(D14 & " 1"),"") -> 45839 | B14: Webinar | C14: =IF(D14="","", IF(A14<DATE(2025, 4, 1),"Q1",if(A14<DATE(2025, 7, 1),"Q2",IF(A14<DATE(2025, 10, 1),"Q3","Q4")))) -> Q3 | D14: July | E14: Webinar | F14: 200 | G14: 3 | H14: 3 | K14: =IFERROR(F14/G14,"") -> 66.666667 | L14: =SUM(M14:O14) -> 0 | U14: =if(T14<=0,"",((T14*12)-F14)/F14) | V14: =iferror(L14/P14,"") | W14: =iferror(Q14/L14,"") | X14: =iferror(R14/Q14,"") | Y14: =iferror(R14/L14,"")
A15: =iferror(DATEVALUE(D15 & " 1"),"") -> 45870 | B15: Webinar | C15: =IF(D15="","", IF(A15<DATE(2025, 4, 1),"Q1",if(A15<DATE(2025, 7, 1),"Q2",IF(A15<DATE(2025, 10, 1),"Q3","Q4")))) -> Q3 | D15: August | E15: Webinar | F15: 200 | G15: 3 | H15: 3 | K15: =IFERROR(F15/G15,"") -> 66.666667 | L15: =SUM(M15:O15) -> 0 | U15: =if(T15<=0,"",((T15*12)-F15)/F15) | V15: =iferror(L15/P15,"") | W15: =iferror(Q15/L15,"") | X15: =iferror(R15/Q15,"") | Y15: =iferror(R15/L15,"")
A16: =iferror(DATEVALUE(D16 & " 1"),"") -> 45901 | B16: Webinar | C16: =IF(D16="","", IF(A16<DATE(2025, 4, 1),"Q1",if(A16<DATE(2025, 7, 1),"Q2",IF(A16<DATE(2025, 10, 1),"Q3","Q4")))) -> Q3 | D16: September | E16: Webinar | F16: 200 | G16: 5 | H16: 5 | K16: =IFERROR(F16/G16,"") -> 40 | L16: =SUM(M16:O16) -> 0 | U16: =if(T16<=0,"",((T16*12)-F16)/F16) | V16: =iferror(L16/P16,"") | W16: =iferror(Q16/L16,"") | X16: =iferror(R16/Q16,"") | Y16: =iferror(R16/L16,"")
A17: =iferror(DATEVALUE(D17 & " 1"),"") -> 45931 | B17: Webinar | C17: =IF(D17="","", IF(A17<DATE(2025, 4, 1),"Q1",if(A17<DATE(2025, 7, 1),"Q2",IF(A17<DATE(2025, 10, 1),"Q3","Q4")))) -> Q4 | D17: October | E17: Webinar | F17: 200 | G17: 3 | H17: 3 | K17: =IFERROR(F17/G17,"") -> 66.666667 | L17: =SUM(M17:O17) -> 0 | U17: =if(T17<=0,"",((T17*12)-F17)/F17) | V17: =iferror(L17/P17,"") | W17: =iferror(Q17/L17,"") | X17: =iferror(R17/Q17,"") | Y17: =iferror(R17/L17,"")
A18: =iferror(DATEVALUE(D18 & " 1"),"") -> 45962 | B18: Webinar | C18: =IF(D18="","", IF(A18<DATE(2025, 4, 1),"Q1",if(A18<DATE(2025, 7, 1),"Q2",IF(A18<DATE(2025, 10, 1),"Q3","Q4")))) -> Q4 | D18: November | E18: Webinar | F18: 200 | G18: 3 | H18: 3 | K18: =IFERROR(F18/G18,"") -> 66.666667 | L18: =SUM(M18:O18) -> 0 | U18: =if(T18<=0,"",((T18*12)-F18)/F18) | V18: =iferror(L18/P18,"") | W18: =iferror(Q18/L18,"") | X18: =iferror(R18/Q18,"") | Y18: =iferror(R18/L18,"")
A19: =iferror(DATEVALUE(D19 & " 1"),"") -> 45992 | B19: Webinar | C19: =IF(D19="","", IF(A19<DATE(2025, 4, 1),"Q1",if(A19<DATE(2025, 7, 1),"Q2",IF(A19<DATE(2025, 10, 1),"Q3","Q4")))) -> Q4 | D19: December | E19: Webinar | F19: 200 | G19: 3 | H19: 3 | K19: =IFERROR(F19/G19,"") -> 66.666667 | L19: =SUM(M19:O19) -> 0 | U19: =if(T19<=0,"",((T19*12)-F19)/F19) | V19: =iferror(L19/P19,"") | W19: =iferror(Q19/L19,"") | X19: =iferror(R19/Q19,"") | Y19: =iferror(R19/L19,"")
A20: =iferror(DATEVALUE(D20 & " 1"),"") -> 45689 | B20: Roadshow | C20: =IF(D20="","", IF(A20<DATE(2025, 4, 1),"Q1",if(A20<DATE(2025, 7, 1),"Q2",IF(A20<DATE(2025, 10, 1),"Q3","Q4")))) -> Q1 | D20: February | E20: Co-hosted | F20: 10000 | G20: =SUM(H20:J20) -> 30 | H20: 5 | I20: 25 | K20: =IFERROR(F20/G20,"") -> 333.33333 | L20: =SUM(M20:O20) -> 0 | U20: =if(T20<=0,"",((T20*12)-#REF!)/#REF!) | V20: =iferror(L20/P20,"") | W20: =iferror(Q20/L20,"") | X20: =iferror(R20/Q20,"") | Y20: =iferror(R20/L20,"")
A21: =iferror(DATEVALUE(D21 & " 1"),"") -> 45778 | B21: Event 2 | C21: =IF(D21="","", IF(A21<DATE(2025, 4, 1),"Q1",if(A21<DATE(2025, 7, 1),"Q2",IF(A21<DATE(2025, 10, 1),"Q3","Q4")))) -> Q2 | D21: May | E21: Fair / Trade Show | F21: 7500 | G21: =SUM(H21:J21) -> 15 | H21: 10 | I21: 5 | K21: =IFERROR(F21/G21,"") -> 500 | L21: =SUM(M21:O21) -> 0 | U21: =if(T21<=0,"",((T21*12)-F21)/F21) | V21: =iferror(L21/P21,"") | W21: =iferror(Q21/L21,"") | X21: =iferror(R21/Q21,"") | Y21: =iferror(R21/L21,"")
A22: =iferror(DATEVALUE(D22 & " 1"),"") -> 45839 | B22: Event 3 | C22: =IF(D22="","", IF(A22<DATE(2025, 4, 1),"Q1",if(A22<DATE(2025, 7, 1),"Q2",IF(A22<DATE(2025, 10, 1),"Q3","Q4")))) -> Q3 | D22: July | E22: Fair / Trade Show | F22: 7500 | G22: =SUM(H22:J22) -> 15 | H22: 10 | I22: 5 | K22: =IFERROR(F22/G22,"") -> 500 | L22: =SUM(M22:O22) -> 0 | U22: =if(T22<=0,"",((T22*12)-F22)/F22) | V22: =iferror(L22/P22,"") | W22: =iferror(Q22/L22,"") | X22: =iferror(R22/Q22,"") | Y22: =iferror(R22/L22,"")
A23: =iferror(DATEVALUE(D23 & " 1"),"") -> 45931 | B23: Event 4 | C23: =IF(D23="","", IF(A23<DATE(2025, 4, 1),"Q1",if(A23<DATE(2025, 7, 1),"Q2",IF(A23<DATE(2025, 10, 1),"Q3","Q4")))) -> Q4 | D23: October | E23: Fair / Trade Show | F23: 7500 | G23: =SUM(H23:J23) -> 15 | H23: 10 | I23: 5 | K23: =IFERROR(F23/G23,"") -> 500 | L23: =SUM(M23:O23) -> 0 | U23: =if(T23<=0,"",((T23*12)-F23)/F23) | V23: =iferror(L23/P23,"") | W23: =iferror(Q23/L23,"") | X23: =iferror(R23/Q23,"") | Y23: =iferror(R23/L23,"")
A24: =iferror(DATEVALUE(D24 & " 1"),"") | C24: =IF(D24="","", IF(A24<DATE(2025, 4, 1),"Q1",if(A24<DATE(2025, 7, 1),"Q2",IF(A24<DATE(2025, 10, 1),"Q3","Q4")))) | K24: =IFERROR(F24/G24,"") | L24: =SUM(M24:O24) -> 0 | U24: =if(T24<=0,"",((T24*12)-F24)/F24) | V24: =iferror(L24/P24,"") | W24: =iferror(Q24/L24,"") | X24: =iferror(R24/Q24,"") | Y24: =iferror(R24/L24,"")
A25: =iferror(DATEVALUE(D25 & " 1"),"") -> 45658 | B25: Paid | C25: =IF(D25="","", IF(A25<DATE(2025, 4, 1),"Q1",if(A25<DATE(2025, 7, 1),"Q2",IF(A25<DATE(2025, 10, 1),"Q3","Q4")))) -> Q1 | D25: January | E25: Other Inbound | F25: 1000 | G25: =SUM(H25:J25) -> 2 | H25: 2 | K25: =IFERROR(F25/G25,"") -> 500 | L25: =SUM(M25:O25) -> 0 | U25: =if(T25<=0,"",((T25*12)-F25)/F25) | V25: =iferror(L25/P25,"") | W25: =iferror(Q25/L25,"") | X25: =iferror(R25/Q25,"") | Y25: =iferror(R25/L25,"")
A26: =iferror(DATEVALUE(D26 & " 1"),"") -> 45689 | B26: Paid | C26: =IF(D26="","", IF(A26<DATE(2025, 4, 1),"Q1",if(A26<DATE(2025, 7, 1),"Q2",IF(A26<DATE(2025, 10, 1),"Q3","Q4")))) -> Q1 | D26: February | E26: Other Inbound | F26: 1000 | G26: =SUM(H26:J26) -> 3 | H26: 3 | K26: =IFERROR(F26/G26,"") -> 333.33333 | L26: =SUM(M26:O26) -> 0 | U26: =if(T26<=0,"",((T26*12)-F26)/F26) | V26: =iferror(L26/P26,"") | W26: =iferror(Q26/L26,"") | X26: =iferror(R26/Q26,"") | Y26: =iferror(R26/L26,"")
A27: =iferror(DATEVALUE(D27 & " 1"),"") -> 45717 | B27: Paid | C27: =IF(D27="","", IF(A27<DATE(2025, 4, 1),"Q1",if(A27<DATE(2025, 7, 1),"Q2",IF(A27<DATE(2025, 10, 1),"Q3","Q4")))) -> Q1 | D27: March | E27: Other Inbound | F27: 1000 | G27: =SUM(H27:J27) -> 4 | H27: 4 | K27: =IFERROR(F27/G27,"") -> 250 | L27: =SUM(M27:O27) -> 0 | U27: =if(T27<=0,"",((T27*12)-F27)/F27) | V27: =iferror(L27/P27,"") | W27: =iferror(Q27/L27,"") | X27: =iferror(R27/Q27,"") | Y27: =iferror(R27/L27,"")
A28: =iferror(DATEVALUE(D28 & " 1"),"") -> 45748 | B28: Paid | C28: =IF(D28="","", IF(A28<DATE(2025, 4, 1),"Q1",if(A28<DATE(2025, 7, 1),"Q2",IF(A28<DATE(2025, 10, 1),"Q3","Q4")))) -> Q2 | D28: April | E28: Other Inbound | F28: 1000 | G28: =SUM(H28:J28) -> 5 | H28: 5 | K28: =IFERROR(F28/G28,"") -> 200 | L28: =SUM(M28:O28) -> 0 | U28: =if(T28<=0,"",((T28*12)-F28)/F28) | V28: =iferror(L28/P28,"") | W28: =iferror(Q28/L28,"") | X28: =iferror(R28/Q28,"") | Y28: =iferror(R28/L28,"")
B29: Paid | C29: =IF(D29="","", IF(A29<DATE(2025, 4, 1),"Q1",if(A29<DATE(2025, 7, 1),"Q2",IF(A29<DATE(2025, 10, 1),"Q3","Q4")))) -> Q1 | D29: May | E29: Other Inbound | F29: 1000 | G29: =SUM(H29:J29) -> 5 | H29: 5 | K29: =IFERROR(F29/G29,"") -> 200
B30: Paid | C30: =IF(D30="","", IF(A30<DATE(2025, 4, 1),"Q1",if(A30<DATE(2025, 7, 1),"Q2",IF(A30<DATE(2025, 10, 1),"Q3","Q4")))) -> Q1 | D30: June | E30: Other Inbound | F30: 1000 | G30: =SUM(H30:J30) -> 5 | H30: 5 | K30: =IFERROR(F30/G30,"") -> 200
B31: Paid | C31: =IF(D31="","", IF(A31<DATE(2025, 4, 1),"Q1",if(A31<DATE(2025, 7, 1),"Q2",IF(A31<DATE(2025, 10, 1),"Q3","Q4")))) -> Q1 | D31: July | E31: Other Inbound | F31: 1000 | G31: =SUM(H31:J31) -> 5 | H31: 5 | K31: =IFERROR(F31/G31,"") -> 200
A32: =iferror(DATEVALUE(D32 & " 1"),"") -> 45870 | B32: Paid | C32: =IF(D32="","", IF(A32<DATE(2025, 4, 1),"Q1",if(A32<DATE(2025, 7, 1),"Q2",IF(A32<DATE(2025, 10, 1),"Q3","Q4")))) -> Q3 | D32: August | E32: Other Inbound | F32: 1000 | G32: =SUM(H32:J32) -> 5 | H32: 5 | K32: =IFERROR(F32/G32,"") -> 200 | L32: =SUM(M32:O32) -> 0 | U32: =if(T32<=0,"",((T32*12)-F32)/F32) | V32: =iferror(L32/P32,"") | W32: =iferror(Q32/L32,"") | X32: =iferror(R32/Q32,"") | Y32: =iferror(R32/L32,"")
A33: =iferror(DATEVALUE(D33 & " 1"),"") -> 45901 | B33: Paid | C33: =IF(D33="","", IF(A33<DATE(2025, 4, 1),"Q1",if(A33<DATE(2025, 7, 1),"Q2",IF(A33<DATE(2025, 10, 1),"Q3","Q4")))) -> Q3 | D33: September | E33: Other Inbound | F33: 1000 | G33: 6 | H33: 6 | K33: =IFERROR(F33/G33,"") -> 166.66667 | L33: =SUM(M33:O33) -> 0 | U33: =if(T33<=0,"",((T33*12)-F33)/F33) | V33: =iferror(L33/P33,"") | W33: =iferror(Q33/L33,"") | X33: =iferror(R33/Q33,"") | Y33: =iferror(R33/L33,"")
A34: =iferror(DATEVALUE(D34 & " 1"),"") -> 45931 | B34: Paid | C34: =IF(D34="","", IF(A34<DATE(2025, 4, 1),"Q1",if(A34<DATE(2025, 7, 1),"Q2",IF(A34<DATE(2025, 10, 1),"Q3","Q4")))) -> Q4 | D34: October | E34: Other Inbound | F34: 1000 | G34: =SUM(H34:J34) -> 5 | H34: 5 | K34: =IFERROR(F34/G34,"") -> 200 | L34: =SUM(M34:O34) -> 0 | U34: =if(T34<=0,"",((T34*12)-F34)/F34) | V34: =iferror(L34/P34,"") | W34: =iferror(Q34/L34,"") | X34: =iferror(R34/Q34,"") | Y34: =iferror(R34/L34,"")
A35: =iferror(DATEVALUE(D35 & " 1"),"") -> 45962 | B35: Paid | C35: =IF(D35="","", IF(A35<DATE(2025, 4, 1),"Q1",if(A35<DATE(2025, 7, 1),"Q2",IF(A35<DATE(2025, 10, 1),"Q3","Q4")))) -> Q4 | D35: November | E35: Other Inbound | F35: 1000 | G35: =SUM(H35:J35) -> 5 | H35: 5 | K35: =IFERROR(F35/G35,"") -> 200 | L35: =SUM(M35:O35) -> 0 | U35: =if(T35<=0,"",((T35*12)-F35)/F35) | V35: =iferror(L35/P35,"") | W35: =iferror(Q35/L35,"") | X35: =iferror(R35/Q35,"") | Y35: =iferror(R35/L35,"")
A36: =iferror(DATEVALUE(D36 & " 1"),"") -> 45992 | B36: Paid | C36: =IF(D36="","", IF(A36<DATE(2025, 4, 1),"Q1",if(A36<DATE(2025, 7, 1),"Q2",IF(A36<DATE(2025, 10, 1),"Q3","Q4")))) -> Q4 | D36: December | E36: Other Inbound | F36: 1000 | G36: =SUM(H36:J36) -> 5 | H36: 5 | K36: =IFERROR(F36/G36,"") -> 200 | L36: =SUM(M36:O36) -> 0 | U36: =if(T36<=0,"",((T36*12)-F36)/F36) | V36: =iferror(L36/P36,"") | W36: =iferror(Q36/L36,"") | X36: =iferror(R36/Q36,"") | Y36: =iferror(R36/L36,"")
A37: =iferror(DATEVALUE(D37 & " 1"),"") | C37: =IF(D37="","", IF(A37<DATE(2025, 4, 1),"Q1",if(A37<DATE(2025, 7, 1),"Q2",IF(A37<DATE(2025, 10, 1),"Q3","Q4")))) | K37: =IFERROR(F37/G37,"") | L37: =SUM(M37:O37) -> 0 | U37: =if(T37<=0,"",((T37*12)-F37)/F37) | V37: =iferror(L37/P37,"") | W37: =iferror(Q37/L37,"") | X37: =iferror(R37/Q37,"") | Y37: =iferror(R37/L37,"")
A38: =iferror(DATEVALUE(D38 & " 1"),"") | C38: =IF(D38="","", IF(A38<DATE(2025, 4, 1),"Q1",if(A38<DATE(2025, 7, 1),"Q2",IF(A38<DATE(2025, 10, 1),"Q3","Q4")))) | K38: =IFERROR(F38/G38,"") | L38: =SUM(M38:O38) -> 0 | U38: =if(T38<=0,"",((T38*12)-F38)/F38) | V38: =iferror(L38/P38,"") | W38: =iferror(Q38/L38,"") | X38: =iferror(R38/Q38,"") | Y38: =iferror(R38/L38,"")
A39: =iferror(DATEVALUE(D39 & " 1"),"") | C39: =IF(D39="","", IF(A39<DATE(2025, 4, 1),"Q1",if(A39<DATE(2025, 7, 1),"Q2",IF(A39<DATE(2025, 10, 1),"Q3","Q4")))) | K39: =IFERROR(F39/G39,"") | L39: =SUM(M39:O39) -> 0 | U39: =if(T39<=0,"",((T39*12)-F39)/F39) | V39: =iferror(L39/P39,"") | W39: =iferror(Q39/L39,"") | X39: =iferror(R39/Q39,"") | Y39: =iferror(R39/L39,"")
A40: =iferror(DATEVALUE(D40 & " 1"),"") | C40: =IF(D40="","", IF(A40<DATE(2025, 4, 1),"Q1",if(A40<DATE(2025, 7, 1),"Q2",IF(A40<DATE(2025, 10, 1),"Q3","Q4")))) | K40: =IFERROR(F40/G40,"") | L40: =SUM(M40:O40) -> 0 | U40: =if(T40<=0,"",((T40*12)-F40)/F40) | V40: =iferror(L40/P40,"") | W40: =iferror(Q40/L40,"") | X40: =iferror(R40/Q40,"") | Y40: =iferror(R40/L40,"")
...

Sheet Headcount
G1: 1 | H1: 2 | I1: 3 | J1: 4 | K1: 5 | L1: 6 | M1: 7 | N1: 8 | O1: 9 | P1: 10 | Q1: 11 | R1: 12 | T1: 12
C2: Dedicated Staff | D2: YES | G2: January | H2: February | I2: March | J2: April | K2: May | L2: June | M2: July | N2: August | O2: September | P2: October | Q2: November | R2: December | T2: TOTAL
C3: Total Annual Investment | D3: =SUM(G3:R3) -> -170600 | F3: Total Staff | G3: =if($D$2="YES",G9+G18+G27+G36+G45,"") -> -14216.667 | H3: =if($D$2="YES",H9+H18+H27+H36+H45,"") -> -14216.667 | I3: =if($D$2="YES",I9+I18+I27+I36+I45,"") -> -14216.667 | J3: =if($D$2="YES",J9+J18+J27+J36+J45,"") -> -14216.667 | K3: =if($D$2="YES",K9+K18+K27+K36+K45,"") -> -14216.667 | L3: =if($D$2="YES",L9+L18+L27+L36+L45,"") -> -14216.667 | M3: =if($D$2="YES",M9+M18+M27+M36+M45,"") -> -14216.667 | N3: =if($D$2="YES",N9+N18+N27+N36+N45,"") -> -14216.667 | ... R3: =if($D$2="YES",R9+R18+R27+R36+R45,"") -> -14216.667 | T3: =SUM(G3:R3) -> -170600
F4: Salary | G4: =if($D$2="YES",G10+G19+G28+G37+G46+G55+G64+G73+G82+G91+G100+G109,"") -> -14216.667 | H4: =if($D$2="YES",H10+H19+H28+H37+H46+H55+H64+H73+H82+H91+H100+H109,"") -> -14216.667 | I4: =if($D$2="YES",I10+I19+I28+I37+I46+I55+I64+I73+I82+I91+I100+I109,"") -> -14216.667 | J4: =if($D$2="YES",J10+J19+J28+J37+J46+J55+J64+J73+J82+J91+J100+J109,"") -> -14216.667 | K4: =if($D$2="YES",K10+K19+K28+K37+K46+K55+K64+K73+K82+K91+K100+K109,"") -> -14216.667 | L4: =if($D$2="YES",L10+L19+L28+L37+L46+L55+L64+L73+L82+L91+L100+L109,"") -> -14216.667 | M4: =if($D$2="YES",M10+M19+M28+M37+M46+M55+M64+M73+M82+M91+M100+M109,"") -> -14216.667 | N4: =if($D$2="YES",N10+N19+N28+N37+N46+N55+N64+N73+N82+N91+N100+N109,"") -> -14216.667 | ... R4: =if($D$2="YES",R10+R19+R28+R37+R46+R55+R64+R73+R82+R91+R100+R109,"") -> -14216.667 | T4: =SUM(G4:R4) -> -170600
F5: Factorial Support | G5: =if($D$2="YES",G11+G20+G29+G38+G47+G56+G65+G74+G83+G92+G101+G110,"") -> 0 | H5: =if($D$2="YES",H11+H20+H29+H38+H47+H56+H65+H74+H83+H92+H101+H110,"") -> 0 | I5: =if($D$2="YES",I11+I20+I29+I38+I47+I56+I65+I74+I83+I92+I101+I110,"") -> 0 | J5: =if($D$2="YES",J11+J20+J29+J38+J47+J56+J65+J74+J83+J92+J101+J110,"") -> 0 | K5: =if($D$2="YES",K11+K20+K29+K38+K47+K56+K65+K74+K83+K92+K101+K110,"") -> 0 | L5: =if($D$2="YES",L11+L20+L29+L38+L47+L56+L65+L74+L83+L92+L101+L110,"") -> 0 | M5: =if($D$2="YES",M11+M20+M29+M38+M47+M56+M65+M74+M83+M92+M101+M110,"") -> 0 | N5: =if($D$2="YES",N11+N20+N29+N38+N47+N56+N65+N74+N83+N92+N101+N110,"") -> 0 | ... R5: =if($D$2="YES",R11+R20+R29+R38+R47+R56+R65+R74+R83+R92+R101+R110,"") -> 0 | T5: =SUM(G5:R5) -> 0
C7: Dedicated Staff Member #1 | D7: YES
C8: Start date | D8: January
C9: Role name | D9: AE 1 (Umar) | F9: =D9 -> AE 1 (Umar) | G9: =G10+G11 -> -7050 | H9: =H10+H11 -> -7050 | I9: =I10+I11 -> -7050 | J9: =J10+J11 -> -7050 | K9: =K10+K11 -> -7050 | L9: =L10+L11 -> -7050 | M9: =M10+M11 -> -7050 | N9: =N10+N11 -> -7050 | ... R9: =R10+R11 -> -7050 | T9: =SUM(G9:R9) -> -84600
C10: Final Annual Cost | D10: =(14000/7*12*1.25+0.3*0.35*35000*12+35000*0.3) -> 84600 | F10: Salary | G10: =IF($D7="YES", IF($D8>0,IF(AND(G$1 >= MATCH($D8, $G$2:$R$2, 0)), -($D10/12), ""),""), "") -> -7050 | H10: =IF($D7="YES", IF($D8>0,IF(AND(H$1 >= MATCH($D8, $G$2:$R$2, 0)), -($D10/12), ""),""), "") -> -7050 | I10: =IF($D7="YES", IF($D8>0,IF(AND(I$1 >= MATCH($D8, $G$2:$R$2, 0)), -($D10/12), ""),""), "") -> -7050 | J10: =IF($D7="YES", IF($D8>0,IF(AND(J$1 >= MATCH($D8, $G$2:$R$2, 0)), -($D10/12), ""),""), "") -> -7050 | K10: =IF($D7="YES", IF($D8>0,IF(AND(K$1 >= MATCH($D8, $G$2:$R$2, 0)), -($D10/12), ""),""), "") -> -7050 | L10: =IF($D7="YES", IF($D8>0,IF(AND(L$1 >= MATCH($D8, $G$2:$R$2, 0)), -($D10/12), ""),""), "") -> -7050 | M10: =IF($D7="YES", IF($D8>0,IF(AND(M$1 >= MATCH($D8, $G$2:$R$2, 0)), -($D10/12), ""),""), "") -> -7050 | N10: =IF($D7="YES", IF($D8>0,IF(AND(N$1 >= MATCH($D8, $G$2:$R$2, 0)), -($D10/12), ""),""), "") -> -7050 | ... R10: =IF($D7="YES", IF($D8>0,IF(AND(R$1 >= MATCH($D8, $G$2:$R$2, 0)), -($D10/12), ""),""), "") -> -7050 | T10: =SUM(G10:R10) -> -84600
C11: Factorial funds? | D11: NO | F11: Factorial Support | G11: =IF($D7="YES", if($D11="YES", IF(AND(G$1 >= MATCH($D14, $G$2:$R$2, 0), G$1 <= (MATCH($D14, $G$2:$R$2, 0) + $D13 - 1)), (($D10/12)*$D12),""),""), "") | H11: =IF($D7="YES", if($D11="YES", IF(AND(H$1 >= MATCH($D14, $G$2:$R$2, 0), H$1 <= (MATCH($D14, $G$2:$R$2, 0) + $D13 - 1)), (($D10/12)*$D12),""),""), "") | I11: =IF($D7="YES", if($D11="YES", IF(AND(I$1 >= MATCH($D14, $G$2:$R$2, 0), I$1 <= (MATCH($D14, $G$2:$R$2, 0) + $D13 - 1)), (($D10/12)*$D12),""),""), "") | J11: =IF($D7="YES", if($D11="YES", IF(AND(J$1 >= MATCH($D14, $G$2:$R$2, 0), J$1 <= (MATCH($D14, $G$2:$R$2, 0) + $D13 - 1)), (($D10/12)*$D12),""),""), "") | K11: =IF($D7="YES", if($D11="YES", IF(AND(K$1 >= MATCH($D14, $G$2:$R$2, 0), K$1 <= (MATCH($D14, $G$2:$R$2, 0) + $D13 - 1)), (($D10/12)*$D12),""),""), "") | L11: =IF($D7="YES", if($D11="YES", IF(AND(L$1 >= MATCH($D14, $G$2:$R$2, 0), L$1 <= (MATCH($D14, $G$2:$R$2, 0) + $D13 - 1)), (($D10/12)*$D12),""),""), "") | M11: =IF($D7="YES", if($D11="YES", IF(AND(M$1 >= MATCH($D14, $G$2:$R$2, 0), M$1 <= (MATCH($D14, $G$2:$R$2, 0) + $D13 - 1)), (($D10/12)*$D12),""),""), "") | N11: =IF($D7="YES", if($D11="YES", IF(AND(N$1 >= MATCH($D14, $G$2:$R$2, 0), N$1 <= (MATCH($D14, $G$2:$R$2, 0) + $D13 - 1)), (($D10/12)*$D12),""),""), "") | ... R11: =IF($D7="YES", if($D11="YES", IF(AND(R$1 >= MATCH($D14, $G$2:$R$2, 0), R$1 <= (MATCH($D14, $G$2:$R$2, 0) + $D13 - 1)), (($D10/12)*$D12),""),""), "") | T11: =SUM(G11:R11) -> 0
C12: % of Factorial Support?
C13: How many months?
C14: First month of funding | D14: January
C16: Dedicated Staff Member #2 | D16: YES
C17: Start date | D17: January
C18: Role name | D18: SDR 1 | F18: =D18 -> SDR 1 | G18: =G19+G20 -> -3854.1667 | H18: =H19+H20 -> -3854.1667 | I18: =I19+I20 -> -3854.1667 | J18: =J19+J20 -> -3854.1667 | K18: =K19+K20 -> -3854.1667 | L18: =L19+L20 -> -3854.1667 | M18: =M19+M20 -> -3854.1667 | N18: =N19+N20 -> -3854.1667 | ... R18: =R19+R20 -> -3854.1667 | T18: =SUM(G18:R18) -> -46250
C19: Final Annual Cost | D19: =25000*1.25+15000 -> 46250 | F19: Salary | G19: =IF($D16="YES", IF($D17>0,IF(AND(G$1 >= MATCH($D17, $G$2:$R$2, 0)), -($D19/12), ""),""), "") -> -3854.1667 | H19: =IF($D16="YES", IF($D17>0,IF(AND(H$1 >= MATCH($D17, $G$2:$R$2, 0)), -($D19/12), ""),""), "") -> -3854.1667 | I19: =IF($D16="YES", IF($D17>0,IF(AND(I$1 >= MATCH($D17, $G$2:$R$2, 0)), -($D19/12), ""),""), "") -> -3854.1667 | J19: =IF($D16="YES", IF($D17>0,IF(AND(J$1 >= MATCH($D17, $G$2:$R$2, 0)), -($D19/12), ""),""), "") -> -3854.1667 | K19: =IF($D16="YES", IF($D17>0,IF(AND(K$1 >= MATCH($D17, $G$2:$R$2, 0)), -($D19/12), ""),""), "") -> -3854.1667 | L19: =IF($D16="YES", IF($D17>0,IF(AND(L$1 >= MATCH($D17, $G$2:$R$2, 0)), -($D19/12), ""),""), "") -> -3854.1667 | M19: =IF($D16="YES", IF($D17>0,IF(AND(M$1 >= MATCH($D17, $G$2:$R$2, 0)), -($D19/12), ""),""), "") -> -3854.1667 | N19: =IF($D16="YES", IF($D17>0,IF(AND(N$1 >= MATCH($D17, $G$2:$R$2, 0)), -($D19/12), ""),""), "") -> -3854.1667 | ... R19: =IF($D16="YES", IF($D17>0,IF(AND(R$1 >= MATCH($D17, $G$2:$R$2, 0)), -($D19/12), ""),""), "") -> -3854.1667 | T19: =SUM(G19:R19) -> -46250
C20: Factorial funds? | D20: NO | F20: Factorial Support | G20: =IF($D16="YES", if($D20="YES", IF(AND(G$1 >= MATCH($D23, $G$2:$R$2, 0), G$1 <= (MATCH($D23, $G$2:$R$2, 0) + $D22 - 1)), (($D19/12)*$D21),""),""), "") | H20: =IF($D16="YES", if($D20="YES", IF(AND(H$1 >= MATCH($D23, $G$2:$R$2, 0), H$1 <= (MATCH($D23, $G$2:$R$2, 0) + $D22 - 1)), (($D19/12)*$D21),""),""), "") | I20: =IF($D16="YES", if($D20="YES", IF(AND(I$1 >= MATCH($D23, $G$2:$R$2, 0), I$1 <= (MATCH($D23, $G$2:$R$2, 0) + $D22 - 1)), (($D19/12)*$D21),""),""), "") | J20: =IF($D16="YES", if($D20="YES", IF(AND(J$1 >= MATCH($D23, $G$2:$R$2, 0), J$1 <= (MATCH($D23, $G$2:$R$2, 0) + $D22 - 1)), (($D19/12)*$D21),""),""), "") | K20: =IF($D16="YES", if($D20="YES", IF(AND(K$1 >= MATCH($D23, $G$2:$R$2, 0), K$1 <= (MATCH($D23, $G$2:$R$2, 0) + $D22 - 1)), (($D19/12)*$D21),""),""), "") | L20: =IF($D16="YES", if($D20="YES", IF(AND(L$1 >= MATCH($D23, $G$2:$R$2, 0), L$1 <= (MATCH($D23, $G$2:$R$2, 0) + $D22 - 1)), (($D19/12)*$D21),""),""), "") | M20: =IF($D16="YES", if($D20="YES", IF(AND(M$1 >= MATCH($D23, $G$2:$R$2, 0), M$1 <= (MATCH($D23, $G$2:$R$2, 0) + $D22 - 1)), (($D19/12)*$D21),""),""), "") | N20: =IF($D16="YES", if($D20="YES", IF(AND(N$1 >= MATCH($D23, $G$2:$R$2, 0), N$1 <= (MATCH($D23, $G$2:$R$2, 0) + $D22 - 1)), (($D19/12)*$D21),""),""), "") | ... R20: =IF($D16="YES", if($D20="YES", IF(AND(R$1 >= MATCH($D23, $G$2:$R$2, 0), R$1 <= (MATCH($D23, $G$2:$R$2, 0) + $D22 - 1)), (($D19/12)*$D21),""),""), "") | T20: =SUM(G20:R20) -> 0
C21: % of Factorial Support? | D21: 0.5
C22: How many months?
C23: First month of funding | D23: January
C25: Dedicated Staff Member #3 | D25: YES
C26: Start date | D26: January
C27: Role name | D27: AE 2 50% | F27: =D27 -> AE 2 50% | G27: =G28+G29 -> 0 | H27: =H28+H29 -> 0 | I27: =I28+I29 -> 0 | J27: =J28+J29 -> 0 | K27: =K28+K29 -> 0 | L27: =L28+L29 -> 0 | M27: =M28+M29 -> 0 | N27: =N28+N29 -> 0 | ... R27: =R28+R29 -> 0 | T27: =SUM(G27:R27) -> 0
C28: Final Annual Cost | D28: 0 | F28: Salary | G28: =IF($D25="YES", IF($D26>0,IF(AND(G$1 >= MATCH($D26, $G$2:$R$2, 0)), -($D28/12), ""),""), "") -> 0 | H28: =IF($D25="YES", IF($D26>0,IF(AND(H$1 >= MATCH($D26, $G$2:$R$2, 0)), -($D28/12), ""),""), "") -> 0 | I28: =IF($D25="YES", IF($D26>0,IF(AND(I$1 >= MATCH($D26, $G$2:$R$2, 0)), -($D28/12), ""),""), "") -> 0 | J28: =IF($D25="YES", IF($D26>0,IF(AND(J$1 >= MATCH($D26, $G$2:$R$2, 0)), -($D28/12), ""),""), "") -> 0 | K28: =IF($D25="YES", IF($D26>0,IF(AND(K$1 >= MATCH($D26, $G$2:$R$2, 0)), -($D28/12), ""),""), "") -> 0 | L28: =IF($D25="YES", IF($D26>0,IF(AND(L$1 >= MATCH($D26, $G$2:$R$2, 0)), -($D28/12), ""),""), "") -> 0 | M28: =IF($D25="YES", IF($D26>0,IF(AND(M$1 >= MATCH($D26, $G$2:$R$2, 0)), -($D28/12), ""),""), "") -> 0 | N28: =IF($D25="YES", IF($D26>0,IF(AND(N$1 >= MATCH($D26, $G$2:$R$2, 0)), -($D28/12), ""),""), "") -> 0 | ... R28: =IF($D25="YES", IF($D26>0,IF(AND(R$1 >= MATCH($D26, $G$2:$R$2, 0)), -($D28/12), ""),""), "") -> 0 | T28: =SUM(G28:R28) -> 0
C29: Factorial funds? | D29: NO | F29: Factorial Support | G29: =IF($D25="YES", if($D29="YES", IF(AND(G$1 >= MATCH($D32, $G$2:$R$2, 0), G$1 <= (MATCH($D32, $G$2:$R$2, 0) + $D31 - 1)), (($D28/12)*$D30),""),""), "") | H29: =IF($D25="YES", if($D29="YES", IF(AND(H$1 >= MATCH($D32, $G$2:$R$2, 0), H$1 <= (MATCH($D32, $G$2:$R$2, 0) + $D31 - 1)), (($D28/12)*$D30),""),""), "") | I29: =IF($D25="YES", if($D29="YES", IF(AND(I$1 >= MATCH($D32, $G$2:$R$2, 0), I$1 <= (MATCH($D32, $G$2:$R$2, 0) + $D31 - 1)), (($D28/12)*$D30),""),""), "") | J29: =IF($D25="YES", if($D29="YES", IF(AND(J$1 >= MATCH($D32, $G$2:$R$2, 0), J$1 <= (MATCH($D32, $G$2:$R$2, 0) + $D31 - 1)), (($D28/12)*$D30),""),""), "") | K29: =IF($D25="YES", if($D29="YES", IF(AND(K$1 >= MATCH($D32, $G$2:$R$2, 0), K$1 <= (MATCH($D32, $G$2:$R$2, 0) + $D31 - 1)), (($D28/12)*$D30),""),""), "") | L29: =IF($D25="YES", if($D29="YES", IF(AND(L$1 >= MATCH($D32, $G$2:$R$2, 0), L$1 <= (MATCH($D32, $G$2:$R$2, 0) + $D31 - 1)), (($D28/12)*$D30),""),""), "") | M29: =IF($D25="YES", if($D29="YES", IF(AND(M$1 >= MATCH($D32, $G$2:$R$2, 0), M$1 <= (MATCH($D32, $G$2:$R$2, 0) + $D31 - 1)), (($D28/12)*$D30),""),""), "") | N29: =IF($D25="YES", if($D29="YES", IF(AND(N$1 >= MATCH($D32, $G$2:$R$2, 0), N$1 <= (MATCH($D32, $G$2:$R$2, 0) + $D31 - 1)), (($D28/12)*$D30),""),""), "") | ... R29: =IF($D25="YES", if($D29="YES", IF(AND(R$1 >= MATCH($D32, $G$2:$R$2, 0), R$1 <= (MATCH($D32, $G$2:$R$2, 0) + $D31 - 1)), (($D28/12)*$D30),""),""), "") | T29: =SUM(G29:R29) -> 0
C30: % of Factorial Support?
C31: How many months?
C32: First month of funding | D32: January
C34: Dedicated Staff Member #4 | D34: YES
C35: Start date | D35: January
C36: Role name | D36: OB/AM specialist | F36: =D36 -> OB/AM specialist | G36: =G37+G38 -> -3312.5 | H36: =H37+H38 -> -3312.5 | I36: =I37+I38 -> -3312.5 | J36: =J37+J38 -> -3312.5 | K36: =K37+K38 -> -3312.5 | L36: =L37+L38 -> -3312.5 | M36: =M37+M38 -> -3312.5 | N36: =N37+N38 -> -3312.5 | ... R36: =R37+R38 -> -3312.5 | T36: =SUM(G36:R36) -> -39750
C37: Final Annual Cost | D37: =27000*1.25+6000 -> 39750 | F37: Salary | G37: =IF($D34="YES", IF($D35>0,IF(AND(G$1 >= MATCH($D35, $G$2:$R$2, 0)), -($D37/12), ""),""), "") -> -3312.5 | H37: =IF($D34="YES", IF($D35>0,IF(AND(H$1 >= MATCH($D35, $G$2:$R$2, 0)), -($D37/12), ""),""), "") -> -3312.5 | I37: =IF($D34="YES", IF($D35>0,IF(AND(I$1 >= MATCH($D35, $G$2:$R$2, 0)), -($D37/12), ""),""), "") -> -3312.5 | J37: =IF($D34="YES", IF($D35>0,IF(AND(J$1 >= MATCH($D35, $G$2:$R$2, 0)), -($D37/12), ""),""), "") -> -3312.5 | K37: =IF($D34="YES", IF($D35>0,IF(AND(K$1 >= MATCH($D35, $G$2:$R$2, 0)), -($D37/12), ""),""), "") -> -3312.5 | L37: =IF($D34="YES", IF($D35>0,IF(AND(L$1 >= MATCH($D35, $G$2:$R$2, 0)), -($D37/12), ""),""), "") -> -3312.5 | M37: =IF($D34="YES", IF($D35>0,IF(AND(M$1 >= MATCH($D35, $G$2:$R$2, 0)), -($D37/12), ""),""), "") -> -3312.5 | N37: =IF($D34="YES", IF($D35>0,IF(AND(N$1 >= MATCH($D35, $G$2:$R$2, 0)), -($D37/12), ""),""), "") -> -3312.5 | ... R37: =IF($D34="YES", IF($D35>0,IF(AND(R$1 >= MATCH($D35, $G$2:$R$2, 0)), -($D37/12), ""),""), "") -> -3312.5 | T37: =SUM(G37:R37) -> -39750
C38: Factorial funds? | D38: NO | F38: Factorial Support | G38: =IF($D34="YES", if($D38="YES", IF(AND(G$1 >= MATCH($D41, $G$2:$R$2, 0), G$1 <= (MATCH($D41, $G$2:$R$2, 0) + $D40 - 1)), (($D37/12)*$D39),""),""), "") | H38: =IF($D34="YES", if($D38="YES", IF(AND(H$1 >= MATCH($D41, $G$2:$R$2, 0), H$1 <= (MATCH($D41, $G$2:$R$2, 0) + $D40 - 1)), (($D37/12)*$D39),""),""), "") | I38: =IF($D34="YES", if($D38="YES", IF(AND(I$1 >= MATCH($D41, $G$2:$R$2, 0), I$1 <= (MATCH($D41, $G$2:$R$2, 0) + $D40 - 1)), (($D37/12)*$D39),""),""), "") | J38: =IF($D34="YES", if($D38="YES", IF(AND(J$1 >= MATCH($D41, $G$2:$R$2, 0), J$1 <= (MATCH($D41, $G$2:$R$2, 0) + $D40 - 1)), (($D37/12)*$D39),""),""), "") | K38: =IF($D34="YES", if($D38="YES", IF(AND(K$1 >= MATCH($D41, $G$2:$R$2, 0), K$1 <= (MATCH($D41, $G$2:$R$2, 0) + $D40 - 1)), (($D37/12)*$D39),""),""), "") | L38: =IF($D34="YES", if($D38="YES", IF(AND(L$1 >= MATCH($D41, $G$2:$R$2, 0), L$1 <= (MATCH($D41, $G$2:$R$2, 0) + $D40 - 1)), (($D37/12)*$D39),""),""), "") | M38: =IF($D34="YES", if($D38="YES", IF(AND(M$1 >= MATCH($D41, $G$2:$R$2, 0), M$1 <= (MATCH($D41, $G$2:$R$2, 0) + $D40 - 1)), (($D37/12)*$D39),""),""), "") | N38: =IF($D34="YES", if($D38="YES", IF(AND(N$1 >= MATCH($D41, $G$2:$R$2, 0), N$1 <= (MATCH($D41, $G$2:$R$2, 0) + $D40 - 1)), (($D37/12)*$D39),""),""), "") | ... R38: =IF($D34="YES", if($D38="YES", IF(AND(R$1 >= MATCH($D41, $G$2:$R$2, 0), R$1 <= (MATCH($D41, $G$2:$R$2, 0) + $D40 - 1)), (($D37/12)*$D39),""),""), "") | T38: =SUM(G38:R38) -> 0
C39: % of Factorial Support?
C40: How many months?
C41: First month of funding
C43: Dedicated Staff Member #5 | D43: NO
C44: Start date
C45: Role name | F45: =D45 | G45: =G46+G47 -> 0 | H45: =H46+H47 -> 0 | I45: =I46+I47 -> 0 | J45: =J46+J47 -> 0 | K45: =K46+K47 -> 0 | L45: =L46+L47 -> 0 | M45: =M46+M47 -> 0 | N45: =N46+N47 -> 0 | ... R45: =R46+R47 -> 0 | T45: =SUM(G45:R45) -> 0
...

Sheet B&I
O1: Actual | Q1: Plan
B2: Incentive Name | C2: KPI | D2: Period | E2: Incentive Type | F2: Amount | G2: Planned Pay Date | H2: Goal | I2: Actual | J2: Achieved? | K2: Amount to pay | L2: Month | O2: MRR | P2: DEMO | Q2: MRR | R2: DEMO
